Workbook

Sheet Cursadas
A1: Ingenieria Informatica
L2: Cursadas | M2: Convalidadas | N2: Totales Necesarias | O2: Quedan
A3: Asignatura | B3: Tipo | C3: Aprobada | D3: Convalidada | E3: Cursando Actualmente | F3: Creditos | G3: Fecha | K3: Básica | L3: =SUMIFS(Cursadas[[#ALL],[Creditos]], Cursadas[[#ALL],[Aprobada]], TRUE, Cursadas[[#ALL],[Tipo]], K3) -> 6 | M3: =SUMIFS(Cursadas[[#ALL],[Creditos]], Cursadas[[#ALL],[Convalidada]], TRUE, Cursadas[[#ALL],[Tipo]], K3) -> 18 | N3: 60 | O3: =N3-M3-L3 -> 36
A4: Lógica | B4: {=VLOOKUP(A4, {Optativas!A:B; Obligatorias!A:B;Basicas!A:B}, 2, FALSE)} -> Básica | C4: TRUE | D4: FALSE | E4: FALSE | F4: {=VLOOKUP(A4, {Optativas!A:C; Obligatorias!A:C;Basicas!A:C}, 3, FALSE)} -> 6 | K4: Obligatoria | L4: =SUMIFS(Cursadas[[#ALL],[Creditos]], Cursadas[[#ALL],[Aprobada]], TRUE, Cursadas[[#ALL],[Tipo]], K4) -> 6 | M4: =SUMIFS(Cursadas[[#ALL],[Creditos]], Cursadas[[#ALL],[Convalidada]], TRUE, Cursadas[[#ALL],[Tipo]], K4) -> 24 | N4: 144 | O4: =N4-M4-L4 -> 114
A5: Análisis y diseño de patrones | B5: {=VLOOKUP(A5, {Optativas!A:B; Obligatorias!A:B;Basicas!A:B}, 2, FALSE)} -> Optativa | C5: TRUE | D5: FALSE | E5: FALSE | F5: {=VLOOKUP(A5, {Optativas!A:C; Obligatorias!A:C;Basicas!A:C}, 3, FALSE)} -> 6 | K5: Optativa | L5: =SUMIFS(Cursadas[[#ALL],[Creditos]], Cursadas[[#ALL],[Aprobada]], TRUE, Cursadas[[#ALL],[Tipo]], K5) -> 6 | M5: =SUMIFS(Cursadas[[#ALL],[Creditos]], Cursadas[[#ALL],[Convalidada]], TRUE, Cursadas[[#ALL],[Tipo]], K5) -> 18 | N5: 36 | O5: =N5-M5-L5 -> 12
A6: Competencia comunicativa para profesionales de las TIC | B6: {=VLOOKUP(A6, {Optativas!A:B; Obligatorias!A:B;Basicas!A:B}, 2, FALSE)} -> Obligatoria | C6: TRUE | D6: FALSE | E6: FALSE | F6: {=VLOOKUP(A6, {Optativas!A:C; Obligatorias!A:C;Basicas!A:C}, 3, FALSE)} -> 6
A7: Fundamentos de programación | B7: {=VLOOKUP(A7, {Optativas!A:B; Obligatorias!A:B;Basicas!A:B}, 2, FALSE)} -> Básica | C7: FALSE | D7: TRUE | E7: FALSE | F7: {=VLOOKUP(A7, {Optativas!A:C; Obligatorias!A:C;Basicas!A:C}, 3, FALSE)} -> 6
A8: Prácticas de programación | B8: {=VLOOKUP(A8, {Optativas!A:B; Obligatorias!A:B;Basicas!A:B}, 2, FALSE)} -> Básica | C8: FALSE | D8: TRUE | E8: FALSE | F8: {=VLOOKUP(A8, {Optativas!A:C; Obligatorias!A:C;Basicas!A:C}, 3, FALSE)} -> 6
A9: Trabajo en equipo en la red | B9: {=VLOOKUP(A9, {Optativas!A:B; Obligatorias!A:B;Basicas!A:B}, 2, FALSE)} -> Básica | C9: FALSE | D9: TRUE | E9: FALSE | F9: {=VLOOKUP(A9, {Optativas!A:C; Obligatorias!A:C;Basicas!A:C}, 3, FALSE)} -> 6
A10: Diseño de bases de datos | B10: {=VLOOKUP(A10, {Optativas!A:B; Obligatorias!A:B;Basicas!A:B}, 2, FALSE)} -> Obligatoria | C10: FALSE | D10: TRUE | E10: FALSE | F10: {=VLOOKUP(A10, {Optativas!A:C; Obligatorias!A:C;Basicas!A:C}, 3, FALSE)} -> 6
A11: Diseño y programación orientada a objetos | B11: {=VLOOKUP(A11, {Optativas!A:B; Obligatorias!A:B;Basicas!A:B}, 2, FALSE)} -> Obligatoria | C11: FALSE | D11: TRUE | E11: FALSE | F11: {=VLOOKUP(A11, {Optativas!A:C; Obligatorias!A:C;Basicas!A:C}, 3, FALSE)} -> 6
A12: Ingeniería del software | B12: {=VLOOKUP(A12, {Optativas!A:B; Obligatorias!A:B;Basicas!A:B}, 2, FALSE)} -> Obligatoria | C12: FALSE | D12: TRUE | E12: FALSE | F12: {=VLOOKUP(A12, {Optativas!A:C; Obligatorias!A:C;Basicas!A:C}, 3, FALSE)} -> 6
A13: Uso de bases de datos | B13: {=VLOOKUP(A13, {Optativas!A:B; Obligatorias!A:B;Basicas!A:B}, 2, FALSE)} -> Obligatoria | C13: FALSE | D13: TRUE | E13: FALSE | F13: {=VLOOKUP(A13, {Optativas!A:C; Obligatorias!A:C;Basicas!A:C}, 3, FALSE)} -> 6
A14: Prácticas en empresa / Més información sobre la matrícula de aquesta asignatura | B14: {=VLOOKUP(A14, {Optativas!A:B; Obligatorias!A:B;Basicas!A:B}, 2, FALSE)} -> Optativa | C14: FALSE | D14: TRUE | E14: FALSE | F14: {=VLOOKUP(A14, {Optativas!A:C; Obligatorias!A:C;Basicas!A:C}, 3, FALSE)} -> 12
A15: Iniciativa emprendedora | B15: {=VLOOKUP(A15, {Optativas!A:B; Obligatorias!A:B;Basicas!A:B}, 2, FALSE)} -> Optativa | C15: FALSE | D15: TRUE | E15: FALSE | F15: {=VLOOKUP(A15, {Optativas!A:C; Obligatorias!A:C;Basicas!A:C}, 3, FALSE)} -> 6
A16: Álgebra | B16: {=VLOOKUP(A16, {Optativas!A:B; Obligatorias!A:B;Basicas!A:B}, 2, FALSE)} -> Básica | C16: FALSE | D16: FALSE | E16: FALSE | F16: {=VLOOKUP(A16, {Optativas!A:C; Obligatorias!A:C;Basicas!A:C}, 3, FALSE)} -> 6
B17: {=VLOOKUP(A17, {Optativas!A:B; Obligatorias!A:B;Basicas!A:B}, 2, FALSE)} -> #N/A | C17: FALSE | D17: FALSE | E17: FALSE | F17: {=VLOOKUP(A17, {Optativas!A:C; Obligatorias!A:C;Basicas!A:C}, 3, FALSE)} -> #N/A

Sheet Basicas
A1: Administración y gestión de organizaciones | B1: Básica | C1: 6 | E1: Empresa | F1: Todos | G1: - | H1: EC + EX o EX
A2: Álgebra | B2: Básica | C2: 6 | E2: Matemáticas | F2: Todos | G2: - | H2: EC + EX
A3: Análisis matemático | B3: Básica | C3: 6 | E3: Matemáticas | F3: Todos | G3: Álgebra
A4: Estadística | B4: Básica | C4: 6 | E4: Matemáticas | F4: Todos | G4: Álgebra
A5: Fundamentos de computadores | B5: Básica | C5: 6 | E5: Informática | F5: Todos | G5: - | H5: EC + EX
A6: Fundamentos de programación | B6: Básica | C6: 6 | E6: Informática | F6: Todos | G6: - | H6: EC
A7: Fundamentos físicos de la informática | B7: Básica | C7: 6 | E7: Física Matematicas | F7: Todos | G7: Álgebra Análisis matemático | H7: EC + EX o EX
A9: Lógica | B9: Básica | C9: 6 | E9: Informática | F9: Todos | H9: EC + PS
A10: Prácticas de programación | B10: Básica | C10: 6 | E10: Informática | F10: Todos | G10: Fundamentos de programación | H10: EC + PS
A11: Trabajo en equipo en la red | B11: Básica | C11: 6 | E11: Informática | F11: Todos | G11: Fundamentos de programación

Sheet Optativas
A1: Análisis y diseño de patrones | B1: Optativa | C1: 6 | D1: Ingeniería del software | F1: Todos | G1: Diseño y programación OO
G2: Ingeniería del Software
A3: Aprendizaje computacional | B3: Optativa | C3: 6 | D3: Computación | F3: Febrero-junio | G3: Inteligencia artificial
A4: Arquitecturas de computadores avanzados | B4: Optativa | C4: 6 | D4: Ingeniería de computadores | F4: Febrero-junio | G4: Arquitectura de computadores
A5: Arquitectura de bases de datos | B5: Optativa | C5: 6 | D5: Tecnologías de la información | F5: Septiembre-febrero | G5: Diseño de base de datos
A6: Arquitectura de computadores | B6: Optativa | C6: 6 | D6: Ingeniería de computadores | F6: Septiembre-febrero | G6: Sistemas operativos
A7: Autómatas y gramáticas | B7: Optativa | C7: 6 | D7: Computación | F7: Febrero-junio | G7: Álgebra
G8: Grafos y complejidad
A9: Comercio electrónico | B9: Optativa | C9: 6 | D9: Tecnologías de la información | F9: Septiembre-febrero | G9: Uso de base de datos
A10: Compiladores | B10: Optativa | C10: 6 | D10: Computación | F10: Septiembre-febrero | G10: Autómatas y gramáticas
G11: Estuctura de computadores
G12: Diseño y programación orientada a objetos
A13: Criptografía | B13: Optativa | C13: 6 | F13: Febrero-junio | G13: Álgebra
G14: Diseño y programación OO
G15: Grafos y complejidad
A16: Planificación y uso estratégico de SI | B16: Optativa | C16: 6 | D16: Sistemas de información | F16: Septiembre-febrero | G16: Gestión Funcional de servicios de SI/TI
G17: Uso de sistemas de información en las organizaciones
A18: Diseño de estructuras de datos | B18: Optativa | C18: 6 | D18: Ingeniería del software | F18: Todos | G18: Diseño y programación OO
D19: Computación | G19: Grafos y complejidad
A20: Diseño de sistemas operativos | B20: Optativa | C20: 6 | D20: Ingeniería de computadores | F20: Septiembre-febrero | G20: Sistemas operativos
A21: Diseño de redes de computadores | B21: Optativa | C21: 6 | D21: Tecnologías de la información | F21: Febrero-junio | G21: Administración de redes y sistemas operativos
G22: Estructura de redes de computadores
A23: Ingeniería de requisitos | B23: Optativa | C23: 6 | D23: Ingeniería del software | F23: Septiembre-febrero | G23: Ingeniería del Software
A24: Ingeniería del software de componentes y sistemas distribudos | B24: Optativa | C24: 6 | D24: Ingeniería del software | F24: Febrero-junio | G24: Análisis y diseño con patrones
G25: Ingeniería del Software
A26: Estructura de redes de computadores | B26: Optativa | C26: 6 | D26: Ingeniería de computadores | F26: Febrero-junio | G26: Redes y aplicaciones Internet
A27: Fundamentos de sistemas de información | B27: Optativa | C27: 6 | D27: Tecnologías de la información | F27: Septiembre-febrero | G27: Gestión de Proyectos
D28: Sistemas de información
A29: Gestión funcional de servicios de SI/TI | B29: Optativa | C29: 6 | D29: Sistemas de información | F29: Febrero-junio | G29: Fundamentos de sistemas de información
A30: Iniciación a las matemáticas para la ingeniería | B30: Optativa | C30: 6 | F30: Todos | G30: -
A31: Iniciativa emprendedora | B31: Optativa | C31: 6 | D31: Sistemas de información | F31: Septiembre-febrero | G31: Gestión de Proyectos
A32: Integración de sistemas de información | B32: Optativa | C32: 6 | D32: Tecnologías de la información | F32: Febrero-junio | G32: Fundamentos de sistemas de información
D33: Sistemas de información
A34: Mineria de datos | B34: Optativa | C34: 6 | D34: Computación | F34: Todos | G34: Estadística
G35: Uso de base de datos
G36: Fundamentos de programación
A37: Prácticas en empresa / Més información sobre la matrícula de aquesta asignatura | B37: Optativa | C37: 12 | F37: Todos | G37: Haber superado 120 créditos
D38: Ingeniería del software | F38: Septiembre-febrero | G38: Diseño de base de datos
G39: Ing. de requisitos
G40: Ing. del software de componentes y sistemas distribuidos
...

Sheet Obligatorias
A1: Administración de redes y sistemas operativos | B1: Obligatoria | C1: 6 | F1: Todos | G1: Sistemas operativos
A2: Competencia comunicativa para profesionales de las TIC | B2: Obligatoria | C2: 6 | F2: Todos | G2: -
A3: Diseño de bases de datos | B3: Obligatoria | C3: 6 | F3: Todos | G3: Uso de base de datos
A4: Diseño y programación orientada a objetos | B4: Obligatoria | C4: 6 | F4: Todos | G4: Ingeniería del software Prácticas de programación
A5: Ingeniería del software | B5: Obligatoria | C5: 6 | F5: Todos | G5: -
A6: Estructura de computadores | B6: Obligatoria | C6: 6 | F6: Todos | G6: Fundamentos de computadores Fundamentos de programación
A7: Gestión de proyectos | B7: Obligatoria | C7: 6 | F7: Todos | G7: Administración y gestión de organizaciones
A8: Grafos y complejidad | B8: Obligatoria | C8: 6 | F8: Todos | G8: Álgebra Lógica Prácticas de programación
A9: Idioma moderno I: inglés | B9: Obligatoria | C9: 6 | F9: Todos
A10: Idioma moderno II: inglés | B10: Obligatoria | C10: 6 | F10: Todos | G10: Idioma moderno I: inglés
A11: Inteligencia artificial | B11: Obligatoria | C11: 6 | F11: Todos | G11: Grafos y complejidad
A12: Interacción persona ordenador | B12: Obligatoria | C12: 6 | F12: Todos | G12: Ingeniería del software
A13: Sistemas distribuidos | B13: Obligatoria | C13: 6 | F13: Todos | G13: Redes y aplicaciones Internet
A14: Sistemas operativos | B14: Obligatoria | C14: 6 | F14: Todos | G14: Estructura de computadores Prácticas de programación
A15: Uso de bases de datos | B15: Obligatoria | C15: 6 | F15: Todos | G15: Diseño y programación OO
A16: Redes y aplicaciones Internet | B16: Obligatoria | C16: 6 | F16: Todos | G16: Diseño y programación OO Sistemas operativos
A17: Trabajo final de grado / Más información sobre el trámite Solicitud del trabajo final | B17: Obligatoria | C17: 12 | D17: Ingeniería de computadores Ingeniería del software Computación Tecnologías de la información Sistemas de información | F17: Todos | G17: Asignaturas del itinerario correspondiente (se pueden cursar algunas en paralelo) / Haber superado 180 créditos / Tener superada la asignatura Gestión de proyectos.

Sheet Itinerarios
A1: Itinerario | B1: Asignaturas | C1: Créditos | D1: Seleccionada | E1: Aprobadas/Convalidadas
A2: Ingeniería de computadores | B2: Administración de redes y sistemas operativos | C2: 48 | D2: =NOT(ISERROR(MATCH(B2, Cursadas[Asignatura], 0))) -> FALSE | E2: {=OR(XLOOKUP(B2, Cursadas[Asignatura], Cursadas[Convalidada], FALSE), XLOOKUP(B2, Cursadas[Asignatura], Cursadas[Aprobada], FALSE))} -> FALSE
B3: Arquitectura de computadores | D3: =NOT(ISERROR(MATCH(B3, Cursadas[Asignatura], 0))) -> FALSE | E3: {=OR(XLOOKUP(B3, Cursadas[Asignatura], Cursadas[Convalidada], FALSE), XLOOKUP(B3, Cursadas[Asignatura], Cursadas[Aprobada], FALSE))} -> FALSE
B4: Arquitectura de computadores avanzados | D4: =NOT(ISERROR(MATCH(B4, Cursadas[Asignatura], 0))) -> FALSE | E4: {=OR(XLOOKUP(B4, Cursadas[Asignatura], Cursadas[Convalidada], FALSE), XLOOKUP(B4, Cursadas[Asignatura], Cursadas[Aprobada], FALSE))} -> FALSE
B5: Diseño de sistemas operativos | D5: =NOT(ISERROR(MATCH(B5, Cursadas[Asignatura], 0))) -> FALSE | E5: {=OR(XLOOKUP(B5, Cursadas[Asignatura], Cursadas[Convalidada], FALSE), XLOOKUP(B5, Cursadas[Asignatura], Cursadas[Aprobada], FALSE))} -> FALSE
B6: Estructura de redes de computadores | D6: =NOT(ISERROR(MATCH(B6, Cursadas[Asignatura], 0))) -> FALSE | E6: {=OR(XLOOKUP(B6, Cursadas[Asignatura], Cursadas[Convalidada], FALSE), XLOOKUP(B6, Cursadas[Asignatura], Cursadas[Aprobada], FALSE))} -> FALSE
B7: Seguridad en redes de computador | D7: =NOT(ISERROR(MATCH(B7, Cursadas[Asignatura], 0))) -> FALSE | E7: {=OR(XLOOKUP(B7, Cursadas[Asignatura], Cursadas[Convalidada], FALSE), XLOOKUP(B7, Cursadas[Asignatura], Cursadas[Aprobada], FALSE))} -> FALSE
B8: Sistemas empotrados | D8: =NOT(ISERROR(MATCH(B8, Cursadas[Asignatura], 0))) -> FALSE | E8: {=OR(XLOOKUP(B8, Cursadas[Asignatura], Cursadas[Convalidada], FALSE), XLOOKUP(B8, Cursadas[Asignatura], Cursadas[Aprobada], FALSE))} -> FALSE
B9: Sistemas distribuidos | D9: =NOT(ISERROR(MATCH(B9, Cursadas[Asignatura], 0))) -> FALSE | E9: {=OR(XLOOKUP(B9, Cursadas[Asignatura], Cursadas[Convalidada], FALSE), XLOOKUP(B9, Cursadas[Asignatura], Cursadas[Aprobada], FALSE))} -> FALSE
A10: Ingeniería del software | B10: Análisis y diseño con patrones | C10: 48 | D10: =NOT(ISERROR(MATCH(B10, Cursadas[Asignatura], 0))) -> FALSE | E10: {=OR(XLOOKUP(B10, Cursadas[Asignatura], Cursadas[Convalidada], FALSE), XLOOKUP(B10, Cursadas[Asignatura], Cursadas[Aprobada], FALSE))} -> FALSE
B11: Diseño de estructuras de datos | D11: =NOT(ISERROR(MATCH(B11, Cursadas[Asignatura], 0))) -> FALSE | E11: {=OR(XLOOKUP(B11, Cursadas[Asignatura], Cursadas[Convalidada], FALSE), XLOOKUP(B11, Cursadas[Asignatura], Cursadas[Aprobada], FALSE))} -> FALSE
B12: Ingeniería del software | D12: =NOT(ISERROR(MATCH(B12, Cursadas[Asignatura], 0))) -> TRUE | E12: {=OR(XLOOKUP(B12, Cursadas[Asignatura], Cursadas[Convalidada], FALSE), XLOOKUP(B12, Cursadas[Asignatura], Cursadas[Aprobada], FALSE))} -> TRUE
B13: Ingeniería del software de componentes y sistemas distribuidos | D13: =NOT(ISERROR(MATCH(B13, Cursadas[Asignatura], 0))) -> FALSE | E13: {=OR(XLOOKUP(B13, Cursadas[Asignatura], Cursadas[Convalidada], FALSE), XLOOKUP(B13, Cursadas[Asignatura], Cursadas[Aprobada], FALSE))} -> FALSE
B14: Ingeniería de requisitos | D14: =NOT(ISERROR(MATCH(B14, Cursadas[Asignatura], 0))) -> FALSE | E14: {=OR(XLOOKUP(B14, Cursadas[Asignatura], Cursadas[Convalidada], FALSE), XLOOKUP(B14, Cursadas[Asignatura], Cursadas[Aprobada], FALSE))} -> FALSE
B15: Interacción persona ordenador | D15: =NOT(ISERROR(MATCH(B15, Cursadas[Asignatura], 0))) -> FALSE | E15: {=OR(XLOOKUP(B15, Cursadas[Asignatura], Cursadas[Convalidada], FALSE), XLOOKUP(B15, Cursadas[Asignatura], Cursadas[Aprobada], FALSE))} -> FALSE
B16: Proyecto de desarrollo de software | D16: =NOT(ISERROR(MATCH(B16, Cursadas[Asignatura], 0))) -> FALSE | E16: {=OR(XLOOKUP(B16, Cursadas[Asignatura], Cursadas[Convalidada], FALSE), XLOOKUP(B16, Cursadas[Asignatura], Cursadas[Aprobada], FALSE))} -> FALSE
A17: Computación | B17: Aprendizaje computacional | C17: 48 | D17: =NOT(ISERROR(MATCH(B17, Cursadas[Asignatura], 0))) -> FALSE | E17: {=OR(XLOOKUP(B17, Cursadas[Asignatura], Cursadas[Convalidada], FALSE), XLOOKUP(B17, Cursadas[Asignatura], Cursadas[Aprobada], FALSE))} -> FALSE
B18: Autómatas y gramáticas | D18: =NOT(ISERROR(MATCH(B18, Cursadas[Asignatura], 0))) -> FALSE | E18: {=OR(XLOOKUP(B18, Cursadas[Asignatura], Cursadas[Convalidada], FALSE), XLOOKUP(B18, Cursadas[Asignatura], Cursadas[Aprobada], FALSE))} -> FALSE
B19: Compiladores | D19: =NOT(ISERROR(MATCH(B19, Cursadas[Asignatura], 0))) -> FALSE | E19: {=OR(XLOOKUP(B19, Cursadas[Asignatura], Cursadas[Convalidada], FALSE), XLOOKUP(B19, Cursadas[Asignatura], Cursadas[Aprobada], FALSE))} -> FALSE
B20: Diseño de estructuras de datos | D20: =NOT(ISERROR(MATCH(B20, Cursadas[Asignatura], 0))) -> FALSE | E20: {=OR(XLOOKUP(B20, Cursadas[Asignatura], Cursadas[Convalidada], FALSE), XLOOKUP(B20, Cursadas[Asignatura], Cursadas[Aprobada], FALSE))} -> FALSE
B21: Grafos y complejidad | D21: =NOT(ISERROR(MATCH(B21, Cursadas[Asignatura], 0))) -> FALSE | E21: {=OR(XLOOKUP(B21, Cursadas[Asignatura], Cursadas[Convalidada], FALSE), XLOOKUP(B21, Cursadas[Asignatura], Cursadas[Aprobada], FALSE))} -> FALSE
B22: Inteligencia artificial | D22: =NOT(ISERROR(MATCH(B22, Cursadas[Asignatura], 0))) -> FALSE | E22: {=OR(XLOOKUP(B22, Cursadas[Asignatura], Cursadas[Convalidada], FALSE), XLOOKUP(B22, Cursadas[Asignatura], Cursadas[Aprobada], FALSE))} -> FALSE
B23: Minería de datos | D23: =NOT(ISERROR(MATCH(B23, Cursadas[Asignatura], 0))) -> FALSE | E23: {=OR(XLOOKUP(B23, Cursadas[Asignatura], Cursadas[Convalidada], FALSE), XLOOKUP(B23, Cursadas[Asignatura], Cursadas[Aprobada], FALSE))} -> FALSE
B24: Representación del conocimiento | D24: =NOT(ISERROR(MATCH(B24, Cursadas[Asignatura], 0))) -> FALSE | E24: {=OR(XLOOKUP(B24, Cursadas[Asignatura], Cursadas[Convalidada], FALSE), XLOOKUP(B24, Cursadas[Asignatura], Cursadas[Aprobada], FALSE))} -> FALSE
A25: Tecnologías de la información | B25: Administración de redes y sistemas operativos | C25: 48 | D25: =NOT(ISERROR(MATCH(B25, Cursadas[Asignatura], 0))) -> FALSE | E25: {=OR(XLOOKUP(B25, Cursadas[Asignatura], Cursadas[Convalidada], FALSE), XLOOKUP(B25, Cursadas[Asignatura], Cursadas[Aprobada], FALSE))} -> FALSE
B26: Arquitectura de bases de datos | D26: =NOT(ISERROR(MATCH(B26, Cursadas[Asignatura], 0))) -> FALSE | E26: {=OR(XLOOKUP(B26, Cursadas[Asignatura], Cursadas[Convalidada], FALSE), XLOOKUP(B26, Cursadas[Asignatura], Cursadas[Aprobada], FALSE))} -> FALSE
B27: Comercio electrónico | D27: =NOT(ISERROR(MATCH(B27, Cursadas[Asignatura], 0))) -> FALSE | E27: {=OR(XLOOKUP(B27, Cursadas[Asignatura], Cursadas[Convalidada], FALSE), XLOOKUP(B27, Cursadas[Asignatura], Cursadas[Aprobada], FALSE))} -> FALSE
B28: Diseño de redes de computadores | D28: =NOT(ISERROR(MATCH(B28, Cursadas[Asignatura], 0))) -> FALSE | E28: {=OR(XLOOKUP(B28, Cursadas[Asignatura], Cursadas[Convalidada], FALSE), XLOOKUP(B28, Cursadas[Asignatura], Cursadas[Aprobada], FALSE))} -> FALSE
B29: Fundamentos de sistemas de información | D29: =NOT(ISERROR(MATCH(B29, Cursadas[Asignatura], 0))) -> FALSE | E29: {=OR(XLOOKUP(B29, Cursadas[Asignatura], Cursadas[Convalidada], FALSE), XLOOKUP(B29, Cursadas[Asignatura], Cursadas[Aprobada], FALSE))} -> FALSE
B30: Integración de sistemas de información | D30: =NOT(ISERROR(MATCH(B30, Cursadas[Asignatura], 0))) -> FALSE | E30: {=OR(XLOOKUP(B30, Cursadas[Asignatura], Cursadas[Convalidada], FALSE), XLOOKUP(B30, Cursadas[Asignatura], Cursadas[Aprobada], FALSE))} -> FALSE
B31: Interacción persona ordenador | D31: =NOT(ISERROR(MATCH(B31, Cursadas[Asignatura], 0))) -> FALSE | E31: {=OR(XLOOKUP(B31, Cursadas[Asignatura], Cursadas[Convalidada], FALSE), XLOOKUP(B31, Cursadas[Asignatura], Cursadas[Aprobada], FALSE))} -> FALSE
B32: Seguridad en redes de computadores | D32: =NOT(ISERROR(MATCH(B32, Cursadas[Asignatura], 0))) -> FALSE | E32: {=OR(XLOOKUP(B32, Cursadas[Asignatura], Cursadas[Convalidada], FALSE), XLOOKUP(B32, Cursadas[Asignatura], Cursadas[Aprobada], FALSE))} -> FALSE
A33: Sistemas de información | B33: Fundamentos de sistemas de información | C33: 48 | D33: =NOT(ISERROR(MATCH(B33, Cursadas[Asignatura], 0))) -> FALSE | E33: {=OR(XLOOKUP(B33, Cursadas[Asignatura], Cursadas[Convalidada], FALSE), XLOOKUP(B33, Cursadas[Asignatura], Cursadas[Aprobada], FALSE))} -> FALSE
B34: Ingeniería del software | D34: =NOT(ISERROR(MATCH(B34, Cursadas[Asignatura], 0))) -> TRUE | E34: {=OR(XLOOKUP(B34, Cursadas[Asignatura], Cursadas[Convalidada], FALSE), XLOOKUP(B34, Cursadas[Asignatura], Cursadas[Aprobada], FALSE))} -> TRUE
B35: Gestión de proyectos | D35: =NOT(ISERROR(MATCH(B35, Cursadas[Asignatura], 0))) -> FALSE | E35: {=OR(XLOOKUP(B35, Cursadas[Asignatura], Cursadas[Convalidada], FALSE), XLOOKUP(B35, Cursadas[Asignatura], Cursadas[Aprobada], FALSE))} -> FALSE
B36: Gestión funcional de servicios SI/TI | D36: =NOT(ISERROR(MATCH(B36, Cursadas[Asignatura], 0))) -> FALSE | E36: {=OR(XLOOKUP(B36, Cursadas[Asignatura], Cursadas[Convalidada], FALSE), XLOOKUP(B36, Cursadas[Asignatura], Cursadas[Aprobada], FALSE))} -> FALSE
B37: Iniciativa emprendedora | D37: =NOT(ISERROR(MATCH(B37, Cursadas[Asignatura], 0))) -> TRUE | E37: {=OR(XLOOKUP(B37, Cursadas[Asignatura], Cursadas[Convalidada], FALSE), XLOOKUP(B37, Cursadas[Asignatura], Cursadas[Aprobada], FALSE))} -> TRUE
B38: Integración de sistemas de información | D38: =NOT(ISERROR(MATCH(B38, Cursadas[Asignatura], 0))) -> FALSE | E38: {=OR(XLOOKUP(B38, Cursadas[Asignatura], Cursadas[Convalidada], FALSE), XLOOKUP(B38, Cursadas[Asignatura], Cursadas[Aprobada], FALSE))} -> FALSE
B39: Planificación y uso estratégico de sistemas de información | D39: =NOT(ISERROR(MATCH(B39, Cursadas[Asignatura], 0))) -> FALSE | E39: {=OR(XLOOKUP(B39, Cursadas[Asignatura], Cursadas[Convalidada], FALSE), XLOOKUP(B39, Cursadas[Asignatura], Cursadas[Aprobada], FALSE))} -> FALSE
B40: Uso de sistemas de información en las organizaciones | D40: =NOT(ISERROR(MATCH(B40, Cursadas[Asignatura], 0))) -> FALSE | E40: {=OR(XLOOKUP(B40, Cursadas[Asignatura], Cursadas[Convalidada], FALSE), XLOOKUP(B40, Cursadas[Asignatura], Cursadas[Aprobada], FALSE))} -> FALSE

Sheet Convalidadas
A1: Convalidadas DAW
B2: Asignatura | C2: Tipo | D2: Creditos
B3: Fundamentos de programación | C3: Básica | D3: 6
B4: Prácticas de programación | C4: Básica | D4: 6
B5: Trabajo en equipo en la red | C5: Básica | D5: 6
B6: Diseño de bases de datos | C6: Obligatoria | D6: 6
B7: Diseño y programación orientada a objetos | C7: Obligatoria | D7: 6
B8: Ingeniería del software | C8: Obligatoria | D8: 6
B9: Uso de bases de datos | C9: Obligatoria | D9: 6
B10: Prácticas en empresa / Més información sobre la matrícula de aquesta asignatura | C10: Optativa | D10: 12
B11: Iniciativa emprendedora | C11: Optativa | D11: 6

Sheet Total Asignaturas
A1: Total Asignatutas
A2: Análisis y diseño de patrones | D2: =IFERROR(__xludf.DUMMYFUNCTION("FILTER(Total_[Total Asignatutas], ISNA(MATCH(Total_[Total Asignatutas],Cursadas[Asignatura], 0)))"),"Aprendizaje computacional") -> Aprendizaje computacional
A3: Aprendizaje computacional | D3: =IFERROR(__xludf.DUMMYFUNCTION("""COMPUTED_VALUE"""),"Arquitecturas de computadores avanzados") -> Arquitecturas de computadores avanzados
A4: Arquitecturas de computadores avanzados | D4: =IFERROR(__xludf.DUMMYFUNCTION("""COMPUTED_VALUE"""),"Arquitectura de bases de datos") -> Arquitectura de bases de datos
A5: Arquitectura de bases de datos | D5: =IFERROR(__xludf.DUMMYFUNCTION("""COMPUTED_VALUE"""),"Arquitectura de computadores") -> Arquitectura de computadores
A6: Arquitectura de computadores | D6: =IFERROR(__xludf.DUMMYFUNCTION("""COMPUTED_VALUE"""),"Autómatas y gramáticas") -> Autómatas y gramáticas
A7: Autómatas y gramáticas | D7: =IFERROR(__xludf.DUMMYFUNCTION("""COMPUTED_VALUE"""),"Comercio electrónico") -> Comercio electrónico
A8: Comercio electrónico | D8: =IFERROR(__xludf.DUMMYFUNCTION("""COMPUTED_VALUE"""),"Compiladores") -> Compiladores
A9: Compiladores | D9: =IFERROR(__xludf.DUMMYFUNCTION("""COMPUTED_VALUE"""),"Criptografía") -> Criptografía
A10: Criptografía | D10: =IFERROR(__xludf.DUMMYFUNCTION("""COMPUTED_VALUE"""),"Planificación y uso estratégico de SI") -> Planificación y uso estratégico de SI
A11: Planificación y uso estratégico de SI | D11: =IFERROR(__xludf.DUMMYFUNCTION("""COMPUTED_VALUE"""),"Diseño de estructuras de datos") -> Diseño de estructuras de datos
A12: Diseño de estructuras de datos | D12: =IFERROR(__xludf.DUMMYFUNCTION("""COMPUTED_VALUE"""),"Diseño de sistemas operativos") -> Diseño de sistemas operativos
A13: Diseño de sistemas operativos | D13: =IFERROR(__xludf.DUMMYFUNCTION("""COMPUTED_VALUE"""),"Diseño de redes de computadores") -> Diseño de redes de computadores
A14: Diseño de redes de computadores | D14: =IFERROR(__xludf.DUMMYFUNCTION("""COMPUTED_VALUE"""),"Ingeniería de requisitos") -> Ingeniería de requisitos
A15: Ingeniería de requisitos | D15: =IFERROR(__xludf.DUMMYFUNCTION("""COMPUTED_VALUE"""),"Ingeniería del software de componentes y sistemas distribudos") -> Ingeniería del software de componentes y sistemas distribudos
A16: Ingeniería del software de componentes y sistemas distribudos | D16: =IFERROR(__xludf.DUMMYFUNCTION("""COMPUTED_VALUE"""),"Estructura de redes de computadores") -> Estructura de redes de computadores
A17: Estructura de redes de computadores | D17: =IFERROR(__xludf.DUMMYFUNCTION("""COMPUTED_VALUE"""),"Fundamentos de sistemas de información") -> Fundamentos de sistemas de información
A18: Fundamentos de sistemas de información | D18: =IFERROR(__xludf.DUMMYFUNCTION("""COMPUTED_VALUE"""),"Gestión funcional de servicios de SI/TI") -> Gestión funcional de servicios de SI/TI
A19: Gestión funcional de servicios de SI/TI | D19: =IFERROR(__xludf.DUMMYFUNCTION("""COMPUTED_VALUE"""),"Iniciación a las matemáticas para la ingeniería") -> Iniciación a las matemáticas para la ingeniería
A20: Iniciación a las matemáticas para la ingeniería | D20: =IFERROR(__xludf.DUMMYFUNCTION("""COMPUTED_VALUE"""),"Integración de sistemas de información") -> Integración de sistemas de información
A21: Iniciativa emprendedora | D21: =IFERROR(__xludf.DUMMYFUNCTION("""COMPUTED_VALUE"""),"Mineria de datos") -> Mineria de datos
A22: Integración de sistemas de información | D22: =IFERROR(__xludf.DUMMYFUNCTION("""COMPUTED_VALUE"""),"Representación del conocimiento") -> Representación del conocimiento
A23: Mineria de datos | D23: =IFERROR(__xludf.DUMMYFUNCTION("""COMPUTED_VALUE"""),"Seguridad en redes de computadores") -> Seguridad en redes de computadores
A24: Prácticas en empresa / Més información sobre la matrícula de aquesta asignatura | D24: =IFERROR(__xludf.DUMMYFUNCTION("""COMPUTED_VALUE"""),"Sistemas empotrados") -> Sistemas empotrados
A25: Representación del conocimiento | D25: =IFERROR(__xludf.DUMMYFUNCTION("""COMPUTED_VALUE"""),"Uso de sistemas de información en las organizaciones") -> Uso de sistemas de información en las organizaciones
A26: Seguridad en redes de computadores | D26: =IFERROR(__xludf.DUMMYFUNCTION("""COMPUTED_VALUE"""),"Pensamiento computacional para aprender a programar") -> Pensamiento computacional para aprender a programar
A27: Sistemas empotrados | D27: =IFERROR(__xludf.DUMMYFUNCTION("""COMPUTED_VALUE"""),"Trabajo final de grado / Más información sobre el trámite Solicitud del trabajo final") -> Trabajo final de grado / Más información sobre el trámite Solicitud del trabajo final
A28: Uso de sistemas de información en las organizaciones | D28: =IFERROR(__xludf.DUMMYFUNCTION("""COMPUTED_VALUE"""),"Administración de redes y sistemas operativos") -> Administración de redes y sistemas operativos
A29: Pensamiento computacional para aprender a programar | D29: =IFERROR(__xludf.DUMMYFUNCTION("""COMPUTED_VALUE"""),"Estructura de computadores") -> Estructura de computadores
A30: Trabajo final de grado / Más información sobre el trámite Solicitud del trabajo final | D30: =IFERROR(__xludf.DUMMYFUNCTION("""COMPUTED_VALUE"""),"Gestión de proyectos") -> Gestión de proyectos
A31: Administración de redes y sistemas operativos | D31: =IFERROR(__xludf.DUMMYFUNCTION("""COMPUTED_VALUE"""),"Grafos y complejidad") -> Grafos y complejidad
A32: Competencia comunicativa para profesionales de las TIC | D32: =IFERROR(__xludf.DUMMYFUNCTION("""COMPUTED_VALUE"""),"Idioma moderno I: inglés") -> Idioma moderno I: inglés
A33: Diseño de bases de datos | D33: =IFERROR(__xludf.DUMMYFUNCTION("""COMPUTED_VALUE"""),"Idioma moderno II: inglés") -> Idioma moderno II: inglés
A34: Diseño y programación orientada a objetos | D34: =IFERROR(__xludf.DUMMYFUNCTION("""COMPUTED_VALUE"""),"Inteligencia artificial") -> Inteligencia artificial
A35: Ingeniería del software | D35: =IFERROR(__xludf.DUMMYFUNCTION("""COMPUTED_VALUE"""),"Interacción persona ordenador") -> Interacción persona ordenador
A36: Estructura de computadores | D36: =IFERROR(__xludf.DUMMYFUNCTION("""COMPUTED_VALUE"""),"Sistemas distribuidos") -> Sistemas distribuidos
A37: Gestión de proyectos | D37: =IFERROR(__xludf.DUMMYFUNCTION("""COMPUTED_VALUE"""),"Sistemas operativos") -> Sistemas operativos
A38: Grafos y complejidad | D38: =IFERROR(__xludf.DUMMYFUNCTION("""COMPUTED_VALUE"""),"Redes y aplicaciones Internet") -> Redes y aplicaciones Internet
A39: Idioma moderno I: inglés | D39: =IFERROR(__xludf.DUMMYFUNCTION("""COMPUTED_VALUE"""),"Trabajo final de grado / Más información sobre el trámite Solicitud del trabajo final") -> Trabajo final de grado / Más información sobre el trámite Solicitud del trabajo final
A40: Idioma moderno II: inglés | D40: =IFERROR(__xludf.DUMMYFUNCTION("""COMPUTED_VALUE"""),"Administración y gestión de organizaciones") -> Administración y gestión de organizaciones
...
